Workbook

Sheet README
A1: PLL Throwing Exposure Workbook, 2019–2026
A2: Source: official PLL stats table exports (8 season files, assumed regular season). Seasons assigned from team lists/player counts; please verify.
A3: Passes and Touches are not recorded by PLL for 2019–2021 (shown as 0 in source; Passes Available = FALSE).
A4: Eligible = Games Played ≥ 3 and field position (A, M, D, SSDM, LSM). Summary sheets use formulas over Player_Season.
A5: Shots/passes are exposure proxies, NOT shoulder load, tissue damage, or injury risk.
A6: Literature values (Vincent et al. 2015) are lab results, not PLL player measurements.

Sheet Load_Model_Assumptions
A1: Shoulder-load model: assumptions (edit blue cells; model sheets recalculate)
A3: Reference ball speed, km/h (Vincent 2015, pro mean) | B3: 138
A4: Assumed typical pass speed, km/h (ASSUMPTION, not measured) | B4: 70
A5: Pass weight = (pass speed / shot speed)^2 | B5: =(B4/B3)^2 -> 0.25729889
A6: Shot weight (reference unit) | B6: 1
A8: Method: relative load = shots x 1 + passes x pass weight. Squared speed is a kinetic-energy proxy for throwing demand.
A9: Output unit: full-effort-shot equivalents. This is a relative exposure index, not joules, joint torque, tissue stress or injury risk.
A10: Pass speeds are assumptions; range tested 55–85 km/h (weights 0.16–0.38). Passes recorded 2022+ only.

Sheet Load_Model_Cumulative
A1: Player | B1: Position | C1: Seasons 2022–26 | D1: Games | E1: Shots | F1: Passes | G1: Modeled cumulative load | H1: Load per game | I1: Pass share of load
A2: Marcus Holman | B2: A | C2: 5 | D2: 52 | E2: 347 | F2: 1566 | G2: =E2*Load_Model_Assumptions!$B$6+F2*Load_Model_Assumptions!$B$5 -> 749.93006 | H2: =IF(D2>0,G2/D2,"") -> 14.421732 | I2: =IF(G2>0,F2*Load_Model_Assumptions!$B$5/G2,"") -> 0.53729018
A3: Michael Sowers | B3: A | C3: 5 | D3: 51 | E3: 341 | F3: 1259 | G3: =E3*Load_Model_Assumptions!$B$6+F3*Load_Model_Assumptions!$B$5 -> 664.9393 | H3: =IF(D3>0,G3/D3,"") -> 13.038025 | I3: =IF(G3>0,F3*Load_Model_Assumptions!$B$5/G3,"") -> 0.48717123
A4: Rob Pannell | B4: A | C4: 5 | D4: 50 | E4: 302 | F4: 1369 | G4: =E4*Load_Model_Assumptions!$B$6+F4*Load_Model_Assumptions!$B$5 -> 654.24218 | H4: =IF(D4>0,G4/D4,"") -> 13.084844 | I4: =IF(G4>0,F4*Load_Model_Assumptions!$B$5/G4,"") -> 0.53839723
A5: Kieran McArdle | B5: A | C5: 5 | D5: 52 | E5: 307 | F5: 1172 | G5: =E5*Load_Model_Assumptions!$B$6+F5*Load_Model_Assumptions!$B$5 -> 608.5543 | H5: =IF(D5>0,G5/D5,"") -> 11.702967 | I5: =IF(G5>0,F5*Load_Model_Assumptions!$B$5/G5,"") -> 0.4955257
A6: Connor Fields | B6: M | C6: 5 | D6: 48 | E6: 321 | F6: 981 | G6: =E6*Load_Model_Assumptions!$B$6+F6*Load_Model_Assumptions!$B$5 -> 573.41021 | H6: =IF(D6>0,G6/D6,"") -> 11.946046 | I6: =IF(G6>0,F6*Load_Model_Assumptions!$B$5/G6,"") -> 0.44019134
A7: Ryder Garnsey | B7: A | C7: 5 | D7: 50 | E7: 264 | F7: 1190 | G7: =E7*Load_Model_Assumptions!$B$6+F7*Load_Model_Assumptions!$B$5 -> 570.18568 | H7: =IF(D7>0,G7/D7,"") -> 11.403714 | I7: =IF(G7>0,F7*Load_Model_Assumptions!$B$5/G7,"") -> 0.53699293
A8: Jeff Teat | B8: A | C8: 4 | D8: 40 | E8: 236 | F8: 1184 | G8: =E8*Load_Model_Assumptions!$B$6+F8*Load_Model_Assumptions!$B$5 -> 540.64188 | H8: =IF(D8>0,G8/D8,"") -> 13.516047 | I8: =IF(G8>0,F8*Load_Model_Assumptions!$B$5/G8,"") -> 0.56348184
A9: Bryan Costabile | B9: M | C9: 5 | D9: 50 | E9: 293 | F9: 962 | G9: =E9*Load_Model_Assumptions!$B$6+F9*Load_Model_Assumptions!$B$5 -> 540.52153 | H9: =IF(D9>0,G9/D9,"") -> 10.810431 | I9: =IF(G9>0,F9*Load_Model_Assumptions!$B$5/G9,"") -> 0.45793093
A10: Mac O'Keefe | B10: M | C10: 5 | D10: 52 | E10: 311 | F10: 882 | G10: =E10*Load_Model_Assumptions!$B$6+F10*Load_Model_Assumptions!$B$5 -> 537.93762 | H10: =IF(D10>0,G10/D10,"") -> 10.344954 | I10: =IF(G10>0,F10*Load_Model_Assumptions!$B$5/G10,"") -> 0.42186605
A11: Tom Schreiber | B11: M | C11: 4 | D11: 37 | E11: 200 | F11: 953 | G11: =E11*Load_Model_Assumptions!$B$6+F11*Load_Model_Assumptions!$B$5 -> 445.20584 | H11: =IF(D11>0,G11/D11,"") -> 12.03259 | I11: =IF(G11>0,F11*Load_Model_Assumptions!$B$5/G11,"") -> 0.55076959
A12: Brennan O'Neill | B12: A | C12: 3 | D12: 31 | E12: 251 | F12: 752 | G12: =E12*Load_Model_Assumptions!$B$6+F12*Load_Model_Assumptions!$B$5 -> 444.48876 | H12: =IF(D12>0,G12/D12,"") -> 14.338347 | I12: =IF(G12>0,F12*Load_Model_Assumptions!$B$5/G12,"") -> 0.43530631
A13: Logan Wisnauskas | B13: A | C13: 5 | D13: 42 | E13: 208 | F13: 915 | G13: =E13*Load_Model_Assumptions!$B$6+F13*Load_Model_Assumptions!$B$5 -> 443.42848 | H13: =IF(D13>0,G13/D13,"") -> 10.557821 | I13: =IF(G13>0,F13*Load_Model_Assumptions!$B$5/G13,"") -> 0.53092774
... A367: Saam Olexo | B367: LSM | C367: 1 | D367: 1 | E367: 0 | F367: 1 | G367: =E367*Load_Model_Assumptions!$B$6+F367*Load_Model_Assumptions!$B$5 -> 0.25729889 | H367: =IF(D367>0,G367/D367,"") -> 0.25729889 | I367: =IF(G367>0,F367*Load_Model_Assumptions!$B$5/G367,"") -> 1

Sheet Player_Season
A1: Season | B1: Player | C1: Team | D1: Position | E1: Games Played | F1: Shots | G1: Shots On Goal | H1: Total Goals | I1: Assists | J1: Passes | K1: Touches | L1: Passes Available | M1: Eligible | N1: Shots per Game | O1: Passes per Game
A2: 2019 | B2: Brent Adams | C2: Redwoods | D2: M | E2: 10 | F2: 35 | G2: 20 | H2: 10 | I2: 1 | J2: 0 | K2: 0 | L2: =FALSE() -> FALSE | M2: Yes | N2: =IF(E2>0,F2/E2,"") -> 3.5 | O2: =IF(AND(E2>0,L2),J2/E2,"")
A3: 2019 | B3: Drew Adams | C3: Archers | D3: G | E3: 6 | F3: 0 | G3: 0 | H3: 0 | I3: 0 | J3: 0 | K3: 0 | L3: =FALSE() -> FALSE | M3: No | N3: =IF(E3>0,F3/E3,"") -> 0 | O3: =IF(AND(E3>0,L3),J3/E3,"")
A4: 2019 | B4: Dominique Alexander | C4: Archers | D4: M | E4: 10 | F4: 3 | G4: 1 | H4: 0 | I4: 1 | J4: 0 | K4: 0 | L4: =FALSE() -> FALSE | M4: Yes | N4: =IF(E4>0,F4/E4,"") -> 0.3 | O4: =IF(AND(E4>0,L4),J4/E4,"")
A5: 2019 | B5: Ryan Ambler | C5: Archers | D5: M | E5: 9 | F5: 14 | G5: 6 | H5: 3 | I5: 7 | J5: 0 | K5: 0 | L5: =FALSE() -> FALSE | M5: Yes | N5: =IF(E5>0,F5/E5,"") -> 1.5555556 | O5: =IF(AND(E5>0,L5),J5/E5,"")
A6: 2019 | B6: Trevor Baptiste | C6: Atlas | D6: FO | E6: 10 | F6: 15 | G6: 4 | H6: 3 | I6: 3 | J6: 0 | K6: 0 | L6: =FALSE() -> FALSE | M6: No | N6: =IF(E6>0,F6/E6,"") -> 1.5 | O6: =IF(AND(E6>0,L6),J6/E6,"")
A7: 2019 | B7: James Barclay | C7: Whipsnakes | D7: D | E7: 4 | F7: 0 | G7: 0 | H7: 0 | I7: 0 | J7: 0 | K7: 0 | L7: =FALSE() -> FALSE | M7: Yes | N7: =IF(E7>0,F7/E7,"") -> 0 | O7: =IF(AND(E7>0,L7),J7/E7,"")
A8: 2019 | B8: Kylor Bellistri | C8: Redwoods | D8: A | E8: 2 | F8: 4 | G8: 3 | H8: 0 | I8: 1 | J8: 0 | K8: 0 | L8: =FALSE() -> FALSE | M8: No | N8: =IF(E8>0,F8/E8,"") -> 2 | O8: =IF(AND(E8>0,L8),J8/E8,"")
A9: 2019 | B9: Wes Berg | C9: Redwoods | D9: A | E9: 4 | F9: 8 | G9: 7 | H9: 4 | I9: 0 | J9: 0 | K9: 0 | L9: =FALSE() -> FALSE | M9: Yes | N9: =IF(E9>0,F9/E9,"") -> 2 | O9: =IF(AND(E9>0,L9),J9/E9,"")
A10: 2019 | B10: Jake Bernhardt | C10: Whipsnakes | D10: M | E10: 9 | F10: 20 | G10: 13 | H10: 5 | I10: 2 | J10: 0 | K10: 0 | L10: =FALSE() -> FALSE | M10: Yes | N10: =IF(E10>0,F10/E10,"") -> 2.2222222 | O10: =IF(AND(E10>0,L10),J10/E10,"")
A11: 2019 | B11: Kyle Bernlohr | C11: Whipsnakes | D11: G | E11: 10 | F11: 0 | G11: 0 | H11: 0 | I11: 0 | J11: 0 | K11: 0 | L11: =FALSE() -> FALSE | M11: No | N11: =IF(E11>0,F11/E11,"") -> 0 | O11: =IF(AND(E11>0,L11),J11/E11,"")
A12: 2019 | B12: Chris Bocklet | C12: Chrome | D12: A | E12: 2 | F12: 1 | G12: 1 | H12: 0 | I12: 0 | J12: 0 | K12: 0 | L12: =FALSE() -> FALSE | M12: No | N12: =IF(E12>0,F12/E12,"") -> 0.5 | O12: =IF(AND(E12>0,L12),J12/E12,"")
A13: 2019 | B13: Mike Bocklet | C13: Chaos | D13: A | E13: 2 | F13: 4 | G13: 2 | H13: 1 | I13: 2 | J13: 0 | K13: 0 | L13: =FALSE() -> FALSE | M13: No | N13: =IF(E13>0,F13/E13,"") -> 2 | O13: =IF(AND(E13>0,L13),J13/E13,"")
... A24: 2019 | B24: Dan Coates | C24: Chaos | D24: D | E24: 1 | F24: 0 | G24: 0 | H24: 0 | I24: 0 | J24: 0 | K24: 0 | L24: =FALSE() -> FALSE | M24: No | N24: =IF(E24>0,F24/E24,"") -> 0 | O24: =IF(AND(E24>0,L24),J24/E24,"")
A25: 2019 | B25: Greg Coholan | C25: Chrome | E25: 0 | F25: 0 | G25: 0 | H25: 0 | I25: 0 | J25: 0 | K25: 0 | L25: =FALSE() -> FALSE | M25: No | N25: =IF(E25>0,F25/E25,"") | O25: =IF(AND(E25>0,L25),J25/E25,"")
A26: 2019 | B26: Jack Concannon | C26: Atlas | D26: G | E26: 10 | F26: 0 | G26: 0 | H26: 0 | I26: 0 | J26: 0 | K26: 0 | L26: =FALSE() -> FALSE | M26: No | N26: =IF(E26>0,F26/E26,"") -> 0 | O26: =IF(AND(E26>0,L26),J26/E26,"")
A27: 2019 | B27: Evan Connell | C27: Archers | D27: D | E27: 3 | F27: 0 | G27: 0 | H27: 0 | I27: 0 | J27: 0 | K27: 0 | L27: =FALSE() -> FALSE | M27: Yes | N27: =IF(E27>0,F27/E27,"") -> 0 | O27: =IF(AND(E27>0,L27),J27/E27,"")
A28: 2019 | B28: Ryan Conrad | C28: Atlas | D28: M | E28: 4 | F28: 3 | G28: 0 | H28: 0 | I28: 0 | J28: 0 | K28: 0 | L28: =FALSE() -> FALSE | M28: Yes | N28: =IF(E28>0,F28/E28,"") -> 0.75 | O28: =IF(AND(E28>0,L28),J28/E28,"")
A29: 2019 | B29: Curtis Corley | C29: Archers | D29: D | E29: 6 | F29: 0 | G29: 0 | H29: 0 | I29: 0 | J29: 0 | K29: 0 | L29: =FALSE() -> FALSE | M29: Yes | N29: =IF(E29>0,F29/E29,"") -> 0 | O29: =IF(AND(E29>0,L29),J29/E29,"")
A30: 2019 | B30: John Crawley | C30: Atlas | D30: M | E30: 7 | F30: 17 | G30: 10 | H30: 5 | I30: 3 | J30: 0 | K30: 0 | L30: =FALSE() -> FALSE | M30: Yes | N30: =IF(E30>0,F30/E30,"") -> 2.4285714 | O30: =IF(AND(E30>0,L30),J30/E30,"")
A31: 2019 | B31: Ned Crotty | C31: Chrome | D31: M | E31: 10 | F31: 46 | G31: 29 | H31: 17 | I31: 9 | J31: 0 | K31: 0 | L31: =FALSE() -> FALSE | M31: Yes | N31: =IF(E31>0,F31/E31,"") -> 4.6 | O31: =IF(AND(E31>0,L31),J31/E31,"")
A32: 2019 | B32: Christian Cuccinello | C32: Archers | D32: A | E32: 8 | F32: 28 | G32: 17 | H32: 8 | I32: 4 | J32: 0 | K32: 0 | L32: =FALSE() -> FALSE | M32: Yes | N32: =IF(E32>0,F32/E32,"") -> 3.5 | O32: =IF(AND(E32>0,L32),J32/E32,"")
A33: 2019 | B33: Matt Danowski | C33: Chrome | D33: M | E33: 10 | F33: 35 | G33: 20 | H33: 8 | I33: 6 | J33: 0 | K33: 0 | L33: =FALSE() -> FALSE | M33: Yes | N33: =IF(E33>0,F33/E33,"") -> 3.5 | O33: =IF(AND(E33>0,L33),J33/E33,"")
A34: 2019 | B34: Steven DeNapoli | C34: Atlas | D34: M | E34: 7 | F34: 1 | G34: 0 | H34: 0 | I34: 2 | J34: 0 | K34: 0 | L34: =FALSE() -> FALSE | M34: Yes | N34: =IF(E34>0,F34/E34,"") -> 0.14285714 | O34: =IF(AND(E34>0,L34),J34/E34,"")
A35: 2019 | B35: Romar Dennis | C35: Chrome | D35: M | E35: 10 | F35: 24 | G35: 8 | H35: 4 | I35: 1 | J35: 0 | K35: 0 | L35: =FALSE() -> FALSE | M35: Yes | N35: =IF(E35>0,F35/E35,"") -> 2.4 | O35: =IF(AND(E35>0,L35),J35/E35,"")
A36: 2019 | B36: Ryan Drenner | C36: Whipsnakes | D36: A | E36: 10 | F36: 61 | G36: 37 | H36: 19 | I36: 1 | J36: 0 | K36: 0 | L36: =FALSE() -> FALSE | M36: Yes | N36: =IF(E36>0,F36/E36,"") -> 6.1 | O36: =IF(AND(E36>0,L36),J36/E36,"")
A37: 2019 | B37: Matthew Dunn | C37: Whipsnakes | D37: D | E37: 10 | F37: 1 | G37: 1 | H37: 0 | I37: 0 | J37: 0 | K37: 0 | L37: =FALSE() -> FALSE | M37: Yes | N37: =IF(E37>0,F37/E37,"") -> 0.1 | O37: =IF(AND(E37>0,L37),J37/E37,"")
... A64: 2019 | B64: Jules Heningburg | C64: Redwoods | D64: A | E64: 10 | F64: 54 | G64: 33 | H64: 21 | I64: 12 | J64: 0 | K64: 0 | L64: =FALSE() -> FALSE | M64: Yes | N64: =IF(E64>0,F64/E64,"") -> 5.4 | O64: =IF(AND(E64>0,L64),J64/E64,"")
A65: 2019 | B65: Austin Henningsen | C65: Chaos | E65: 0 | F65: 0 | G65: 0 | H65: 0 | I65: 0 | J65: 0 | K65: 0 | L65: =FALSE() -> FALSE | M65: No | N65: =IF(E65>0,F65/E65,"") | O65: =IF(AND(E65>0,L65),J65/E65,"")
A66: 2019 | B66: Brent Hiken | C66: Atlas | D66: FO | E66: 2 | F66: 0 | G66: 0 | H66: 0 | I66: 0 | J66: 0 | K66: 0 | L66: =FALSE() -> FALSE | M66: No | N66: =IF(E66>0,F66/E66,"") -> 0 | O66: =IF(AND(E66>0,L66),J66/E66,"")
A67: 2019 | B67: Andrew Hodgson | C67: Atlas | D67: M | E67: 1 | F67: 3 | G67: 2 | H67: 1 | I67: 0 | J67: 0 | K67: 0 | L67: =FALSE() -> FALSE | M67: No | N67: =IF(E67>0,F67/E67,"") -> 3 | O67: =IF(AND(E67>0,L67),J67/E67,"")
A68: 2019 | B68: Marcus Holman | C68: Archers | D68: A | E68: 10 | F68: 74 | G68: 43 | H68: 23 | I68: 7 | J68: 0 | K68: 0 | L68: =FALSE() -> FALSE | M68: Yes | N68: =IF(E68>0,F68/E68,"") -> 7.4 | O68: =IF(AND(E68>0,L68),J68/E68,"")
A69: 2019 | B69: Myles Jones | C69: Chaos | D69: M | E69: 10 | F69: 43 | G69: 19 | H69: 7 | I69: 10 | J69: 0 | K69: 0 | L69: =FALSE() -> FALSE | M69: Yes | N69: =IF(E69>0,F69/E69,"") -> 4.3 | O69: =IF(AND(E69>0,L69),J69/E69,"")
A70: 2019 | B70: Brian Karalunas | C70: Redwoods | D70: LSM | E70: 10 | F70: 4 | G70: 1 | H70: 1 | I70: 2 | J70: 0 | K70: 0 | L70: =FALSE() -> FALSE | M70: Yes | N70: =IF(E70>0,F70/E70,"") -> 0.4 | O70: =IF(AND(E70>0,L70),J70/E70,"")
A71: 2019 | B71: Matt Kavanagh | C71: Redwoods | D71: A | E71: 9 | F71: 54 | G71: 36 | H71: 15 | I71: 8 | J71: 0 | K71: 0 | L71: =FALSE() -> FALSE | M71: Yes | N71: =IF(E71>0,F71/E71,"") -> 6 | O71: =IF(AND(E71>0,L71),J71/E71,"")
A72: 2019 | B72: Connor Kelly | C72: Whipsnakes | D72: M | E72: 8 | F72: 41 | G72: 21 | H72: 10 | I72: 8 | J72: 0 | K72: 0 | L72: =FALSE() -> FALSE | M72: Yes | N72: =IF(E72>0,F72/E72,"") -> 5.125 | O72: =IF(AND(E72>0,L72),J72/E72,"")
A73: 2019 | B73: Jack Kelly | C73: Redwoods | D73: G | E73: 0 | F73: 0 | G73: 0 | H73: 0 | I73: 0 | J73: 0 | K73: 0 | L73: =FALSE() -> FALSE | M73: No | N73: =IF(E73>0,F73/E73,"") | O73: =IF(AND(E73>0,L73),J73/E73,"")
A74: 2019 | B74: Stephen Kelly | C74: Archers | D74: FO | E74: 10 | F74: 8 | G74: 7 | H74: 3 | I74: 4 | J74: 0 | K74: 0 | L74: =FALSE() -> FALSE | M74: No | N74: =IF(E74>0,F74/E74,"") -> 0.8 | O74: =IF(AND(E74>0,L74),J74/E74,"")
A75: 2019 | B75: Thomas Kelly | C75: Chaos | D75: FO | E75: 10 | F75: 7 | G75: 5 | H75: 2 | I75: 0 | J75: 0 | K75: 0 | L75: =FALSE() -> FALSE | M75: No | N75: =IF(E75>0,F75/E75,"") -> 0.7 | O75: =IF(AND(E75>0,L75),J75/E75,"")
A76: 2019 | B76: Larken Kemp | C76: Redwoods | D76: LSM | E76: 6 | F76: 1 | G76: 1 | H76: 1 | I76: 0 | J76: 0 | K76: 0 | L76: =FALSE() -> FALSE | M76: Yes | N76: =IF(E76>0,F76/E76,"") -> 0.16666667 | O76: =IF(AND(E76>0,L76),J76/E76,"")
...

Sheet Season_Summary
A1: Season | B1: Player rows | C1: Eligible players | D1: Total shots (all rows) | E1: Mean shots/game (eligible) | F1: Mean passes/game (eligible)
A2: 2019 | B2: =COUNTIFS(Player_Season!$A$2:$A$1869,A2) -> 169 | C2: =COUNTIFS(Player_Season!$A$2:$A$1869,A2,Player_Season!$M$2:$M$1869,"Yes") -> 123 | D2: =SUMIFS(Player_Season!$F$2:$F$1869,Player_Season!$A$2:$A$1869,A2) -> 2516 | E2: =AVERAGEIFS(Player_Season!$N$2:$N$1869,Player_Season!$A$2:$A$1869,A2,Player_Season!$M$2:$M$1869,"Yes") -> 2.2543167 | F2: =IF(A2>=2022,AVERAGEIFS(Player_Season!$O$2:$O$1869,Player_Season!$A$2:$A$1869,A2,Player_Season!$M$2:$M$1869,"Yes"),"n/a") -> n/a
A3: 2020 | B3: =COUNTIFS(Player_Season!$A$2:$A$1869,A3) -> 174 | C3: =COUNTIFS(Player_Season!$A$2:$A$1869,A3,Player_Season!$M$2:$M$1869,"Yes") -> 128 | D3: =SUMIFS(Player_Season!$F$2:$F$1869,Player_Season!$A$2:$A$1869,A3) -> 1546 | E3: =AVERAGEIFS(Player_Season!$N$2:$N$1869,Player_Season!$A$2:$A$1869,A3,Player_Season!$M$2:$M$1869,"Yes") -> 2.0786272 | F3: =IF(A3>=2022,AVERAGEIFS(Player_Season!$O$2:$O$1869,Player_Season!$A$2:$A$1869,A3,Player_Season!$M$2:$M$1869,"Yes"),"n/a") -> n/a
A4: 2021 | B4: =COUNTIFS(Player_Season!$A$2:$A$1869,A4) -> 262 | C4: =COUNTIFS(Player_Season!$A$2:$A$1869,A4,Player_Season!$M$2:$M$1869,"Yes") -> 148 | D4: =SUMIFS(Player_Season!$F$2:$F$1869,Player_Season!$A$2:$A$1869,A4) -> 2864 | E4: =AVERAGEIFS(Player_Season!$N$2:$N$1869,Player_Season!$A$2:$A$1869,A4,Player_Season!$M$2:$M$1869,"Yes") -> 2.4398327 | F4: =IF(A4>=2022,AVERAGEIFS(Player_Season!$O$2:$O$1869,Player_Season!$A$2:$A$1869,A4,Player_Season!$M$2:$M$1869,"Yes"),"n/a") -> n/a
A5: 2022 | B5: =COUNTIFS(Player_Season!$A$2:$A$1869,A5) -> 247 | C5: =COUNTIFS(Player_Season!$A$2:$A$1869,A5,Player_Season!$M$2:$M$1869,"Yes") -> 157 | D5: =SUMIFS(Player_Season!$F$2:$F$1869,Player_Season!$A$2:$A$1869,A5) -> 3171 | E5: =AVERAGEIFS(Player_Season!$N$2:$N$1869,Player_Season!$A$2:$A$1869,A5,Player_Season!$M$2:$M$1869,"Yes") -> 2.3888232 | F5: =IF(A5>=2022,AVERAGEIFS(Player_Season!$O$2:$O$1869,Player_Season!$A$2:$A$1869,A5,Player_Season!$M$2:$M$1869,"Yes"),"n/a") -> 11.260623
A6: 2023 | B6: =COUNTIFS(Player_Season!$A$2:$A$1869,A6) -> 242 | C6: =COUNTIFS(Player_Season!$A$2:$A$1869,A6,Player_Season!$M$2:$M$1869,"Yes") -> 153 | D6: =SUMIFS(Player_Season!$F$2:$F$1869,Player_Season!$A$2:$A$1869,A6) -> 3354 | E6: =AVERAGEIFS(Player_Season!$N$2:$N$1869,Player_Season!$A$2:$A$1869,A6,Player_Season!$M$2:$M$1869,"Yes") -> 2.468477 | F6: =IF(A6>=2022,AVERAGEIFS(Player_Season!$O$2:$O$1869,Player_Season!$A$2:$A$1869,A6,Player_Season!$M$2:$M$1869,"Yes"),"n/a") -> 11.179391
A7: 2024 | B7: =COUNTIFS(Player_Season!$A$2:$A$1869,A7) -> 246 | C7: =COUNTIFS(Player_Season!$A$2:$A$1869,A7,Player_Season!$M$2:$M$1869,"Yes") -> 153 | D7: =SUMIFS(Player_Season!$F$2:$F$1869,Player_Season!$A$2:$A$1869,A7) -> 3384 | E7: =AVERAGEIFS(Player_Season!$N$2:$N$1869,Player_Season!$A$2:$A$1869,A7,Player_Season!$M$2:$M$1869,"Yes") -> 2.4940813 | F7: =IF(A7>=2022,AVERAGEIFS(Player_Season!$O$2:$O$1869,Player_Season!$A$2:$A$1869,A7,Player_Season!$M$2:$M$1869,"Yes"),"n/a") -> 10.778623
A8: 2025 | B8: =COUNTIFS(Player_Season!$A$2:$A$1869,A8) -> 251 | C8: =COUNTIFS(Player_Season!$A$2:$A$1869,A8,Player_Season!$M$2:$M$1869,"Yes") -> 154 | D8: =SUMIFS(Player_Season!$F$2:$F$1869,Player_Season!$A$2:$A$1869,A8) -> 3345 | E8: =AVERAGEIFS(Player_Season!$N$2:$N$1869,Player_Season!$A$2:$A$1869,A8,Player_Season!$M$2:$M$1869,"Yes") -> 2.507501 | F8: =IF(A8>=2022,AVERAGEIFS(Player_Season!$O$2:$O$1869,Player_Season!$A$2:$A$1869,A8,Player_Season!$M$2:$M$1869,"Yes"),"n/a") -> 11.086003
A9: 2026 | B9: =COUNTIFS(Player_Season!$A$2:$A$1869,A9) -> 277 | C9: =COUNTIFS(Player_Season!$A$2:$A$1869,A9,Player_Season!$M$2:$M$1869,"Yes") -> 157 | D9: =SUMIFS(Player_Season!$F$2:$F$1869,Player_Season!$A$2:$A$1869,A9) -> 3953 | E9: =AVERAGEIFS(Player_Season!$N$2:$N$1869,Player_Season!$A$2:$A$1869,A9,Player_Season!$M$2:$M$1869,"Yes") -> 2.4749931 | F9: =IF(A9>=2022,AVERAGEIFS(Player_Season!$O$2:$O$1869,Player_Season!$A$2:$A$1869,A9,Player_Season!$M$2:$M$1869,"Yes"),"n/a") -> 11.533823

Sheet Position_Summary
A1: Position | B1: Eligible rows 2022–2026 | C1: Mean shots/game | D1: Mean passes/game
A2: A | B2: =COUNTIFS(Player_Season!$D$2:$D$1869,A2,Player_Season!$M$2:$M$1869,"Yes",Player_Season!$A$2:$A$1869,">=2022") -> 153 | C2: =AVERAGEIFS(Player_Season!$N$2:$N$1869,Player_Season!$D$2:$D$1869,A2,Player_Season!$M$2:$M$1869,"Yes",Player_Season!$A$2:$A$1869,">=2022") -> 5.3988409 | D2: =AVERAGEIFS(Player_Season!$O$2:$O$1869,Player_Season!$D$2:$D$1869,A2,Player_Season!$M$2:$M$1869,"Yes",Player_Season!$A$2:$A$1869,">=2022") -> 20.558699
A3: M | B3: =COUNTIFS(Player_Season!$D$2:$D$1869,A3,Player_Season!$M$2:$M$1869,"Yes",Player_Season!$A$2:$A$1869,">=2022") -> 243 | C3: =AVERAGEIFS(Player_Season!$N$2:$N$1869,Player_Season!$D$2:$D$1869,A3,Player_Season!$M$2:$M$1869,"Yes",Player_Season!$A$2:$A$1869,">=2022") -> 3.6978729 | D3: =AVERAGEIFS(Player_Season!$O$2:$O$1869,Player_Season!$D$2:$D$1869,A3,Player_Season!$M$2:$M$1869,"Yes",Player_Season!$A$2:$A$1869,">=2022") -> 14.017386
A4: D | B4: =COUNTIFS(Player_Season!$D$2:$D$1869,A4,Player_Season!$M$2:$M$1869,"Yes",Player_Season!$A$2:$A$1869,">=2022") -> 146 | C4: =AVERAGEIFS(Player_Season!$N$2:$N$1869,Player_Season!$D$2:$D$1869,A4,Player_Season!$M$2:$M$1869,"Yes",Player_Season!$A$2:$A$1869,">=2022") -> 0.29545998 | D4: =AVERAGEIFS(Player_Season!$O$2:$O$1869,Player_Season!$D$2:$D$1869,A4,Player_Season!$M$2:$M$1869,"Yes",Player_Season!$A$2:$A$1869,">=2022") -> 5.8180936
A5: SSDM | B5: =COUNTIFS(Player_Season!$D$2:$D$1869,A5,Player_Season!$M$2:$M$1869,"Yes",Player_Season!$A$2:$A$1869,">=2022") -> 142 | C5: =AVERAGEIFS(Player_Season!$N$2:$N$1869,Player_Season!$D$2:$D$1869,A5,Player_Season!$M$2:$M$1869,"Yes",Player_Season!$A$2:$A$1869,">=2022") -> 0.61704418 | D5: =AVERAGEIFS(Player_Season!$O$2:$O$1869,Player_Season!$D$2:$D$1869,A5,Player_Season!$M$2:$M$1869,"Yes",Player_Season!$A$2:$A$1869,">=2022") -> 6.1465612
A6: LSM | B6: =COUNTIFS(Player_Season!$D$2:$D$1869,A6,Player_Season!$M$2:$M$1869,"Yes",Player_Season!$A$2:$A$1869,">=2022") -> 90 | C6: =AVERAGEIFS(Player_Season!$N$2:$N$1869,Player_Season!$D$2:$D$1869,A6,Player_Season!$M$2:$M$1869,"Yes",Player_Season!$A$2:$A$1869,">=2022") -> 0.59647266 | D6: =AVERAGEIFS(Player_Season!$O$2:$O$1869,Player_Season!$D$2:$D$1869,A6,Player_Season!$M$2:$M$1869,"Yes",Player_Season!$A$2:$A$1869,">=2022") -> 4.1287734

Sheet Career_Exposure
A1: Player | B1: Seasons | C1: First | D1: Last | E1: Games Played | F1: Career Shots | G1: Shots per Game | H1: Position (first listed)
A2: Marcus Holman | B2: 8 | C2: 2019 | D2: 2026 | E2: =SUMIFS(Player_Season!$E$2:$E$1869,Player_Season!$B$2:$B$1869,A2) -> 77 | F2: =SUMIFS(Player_Season!$F$2:$F$1869,Player_Season!$B$2:$B$1869,A2) -> 497 | G2: =IF(E2>0,F2/E2,"") -> 6.4545455 | H2: A
A3: Connor Fields | B3: 8 | C3: 2019 | D3: 2026 | E3: =SUMIFS(Player_Season!$E$2:$E$1869,Player_Season!$B$2:$B$1869,A3) -> 73 | F3: =SUMIFS(Player_Season!$F$2:$F$1869,Player_Season!$B$2:$B$1869,A3) -> 441 | G3: =IF(E3>0,F3/E3,"") -> 6.0410959 | H3: A
A4: Kieran McArdle | B4: 8 | C4: 2019 | D4: 2026 | E4: =SUMIFS(Player_Season!$E$2:$E$1869,Player_Season!$B$2:$B$1869,A4) -> 75 | F4: =SUMIFS(Player_Season!$F$2:$F$1869,Player_Season!$B$2:$B$1869,A4) -> 421 | G4: =IF(E4>0,F4/E4,"") -> 5.6133333 | H4: A
A5: Rob Pannell | B5: 7 | C5: 2020 | D5: 2026 | E5: =SUMIFS(Player_Season!$E$2:$E$1869,Player_Season!$B$2:$B$1869,A5) -> 64 | F5: =SUMIFS(Player_Season!$F$2:$F$1869,Player_Season!$B$2:$B$1869,A5) -> 404 | G5: =IF(E5>0,F5/E5,"") -> 6.3125 | H5: A
A6: Ryder Garnsey | B6: 8 | C6: 2019 | D6: 2026 | E6: =SUMIFS(Player_Season!$E$2:$E$1869,Player_Season!$B$2:$B$1869,A6) -> 74 | F6: =SUMIFS(Player_Season!$F$2:$F$1869,Player_Season!$B$2:$B$1869,A6) -> 387 | G6: =IF(E6>0,F6/E6,"") -> 5.2297297 | H6: A
A7: Bryan Costabile | B7: 7 | C7: 2020 | D7: 2026 | E7: =SUMIFS(Player_Season!$E$2:$E$1869,Player_Season!$B$2:$B$1869,A7) -> 64 | F7: =SUMIFS(Player_Season!$F$2:$F$1869,Player_Season!$B$2:$B$1869,A7) -> 381 | G7: =IF(E7>0,F7/E7,"") -> 5.953125 | H7: M
A8: Connor Kelly | B8: 8 | C8: 2019 | D8: 2026 | E8: =SUMIFS(Player_Season!$E$2:$E$1869,Player_Season!$B$2:$B$1869,A8) -> 62 | F8: =SUMIFS(Player_Season!$F$2:$F$1869,Player_Season!$B$2:$B$1869,A8) -> 375 | G8: =IF(E8>0,F8/E8,"") -> 6.0483871 | H8: M
A9: Tom Schreiber | B9: 8 | C9: 2019 | D9: 2026 | E9: =SUMIFS(Player_Season!$E$2:$E$1869,Player_Season!$B$2:$B$1869,A9) -> 62 | F9: =SUMIFS(Player_Season!$F$2:$F$1869,Player_Season!$B$2:$B$1869,A9) -> 353 | G9: =IF(E9>0,F9/E9,"") -> 5.6935484 | H9: M
A10: Michael Sowers | B10: 6 | C10: 2021 | D10: 2026 | E10: =SUMIFS(Player_Season!$E$2:$E$1869,Player_Season!$B$2:$B$1869,A10) -> 52 | F10: =SUMIFS(Player_Season!$F$2:$F$1869,Player_Season!$B$2:$B$1869,A10) -> 347 | G10: =IF(E10>0,F10/E10,"") -> 6.6730769 | H10: A
A11: Zed Williams | B11: 7 | C11: 2020 | D11: 2026 | E11: =SUMIFS(Player_Season!$E$2:$E$1869,Player_Season!$B$2:$B$1869,A11) -> 42 | F11: =SUMIFS(Player_Season!$F$2:$F$1869,Player_Season!$B$2:$B$1869,A11) -> 342 | G11: =IF(E11>0,F11/E11,"") -> 8.1428571 | H11: A
A12: Mac O'Keefe | B12: 6 | C12: 2021 | D12: 2026 | E12: =SUMIFS(Player_Season!$E$2:$E$1869,Player_Season!$B$2:$B$1869,A12) -> 61 | F12: =SUMIFS(Player_Season!$F$2:$F$1869,Player_Season!$B$2:$B$1869,A12) -> 340 | G12: =IF(E12>0,F12/E12,"") -> 5.5737705 | H12: A
A13: Matt Rambo | B13: 8 | C13: 2019 | D13: 2026 | E13: =SUMIFS(Player_Season!$E$2:$E$1869,Player_Season!$B$2:$B$1869,A13) -> 62 | F13: =SUMIFS(Player_Season!$F$2:$F$1869,Player_Season!$B$2:$B$1869,A13) -> 329 | G13: =IF(E13>0,F13/E13,"") -> 5.3064516 | H13: A
... A356: Kyle McClancy | B356: 3 | C356: 2019 | D356: 2021 | E356: =SUMIFS(Player_Season!$E$2:$E$1869,Player_Season!$B$2:$B$1869,A356) -> 15 | F356: =SUMIFS(Player_Season!$F$2:$F$1869,Player_Season!$B$2:$B$1869,A356) -> 4 | G356: =IF(E356>0,F356/E356,"") -> 0.26666667 | H356: M
A357: John Uppgren | B357: 1 | C357: 2021 | D357: 2021 | E357: =SUMIFS(Player_Season!$E$2:$E$1869,Player_Season!$B$2:$B$1869,A357) -> 2 | F357: =SUMIFS(Player_Season!$F$2:$F$1869,Player_Season!$B$2:$B$1869,A357) -> 4 | G357: =IF(E357>0,F357/E357,"") -> 2
A358: Kylor Bellistri | B358: 1 | C358: 2019 | D358: 2019 | E358: =SUMIFS(Player_Season!$E$2:$E$1869,Player_Season!$B$2:$B$1869,A358) -> 2 | F358: =SUMIFS(Player_Season!$F$2:$F$1869,Player_Season!$B$2:$B$1869,A358) -> 4 | G358: =IF(E358>0,F358/E358,"") -> 2 | H358: A
A359: Mike O'Neil | B359: 1 | C359: 2019 | D359: 2019 | E359: =SUMIFS(Player_Season!$E$2:$E$1869,Player_Season!$B$2:$B$1869,A359) -> 7 | F359: =SUMIFS(Player_Season!$F$2:$F$1869,Player_Season!$B$2:$B$1869,A359) -> 4 | G359: =IF(E359>0,F359/E359,"") -> 0.57142857 | H359: M
A360: Brian Karalunas | B360: 3 | C360: 2019 | D360: 2021 | E360: =SUMIFS(Player_Season!$E$2:$E$1869,Player_Season!$B$2:$B$1869,A360) -> 10 | F360: =SUMIFS(Player_Season!$F$2:$F$1869,Player_Season!$B$2:$B$1869,A360) -> 4 | G360: =IF(E360>0,F360/E360,"") -> 0.4 | H360: LSM
A361: Jeff Conner | B361: 1 | C361: 2023 | D361: 2023 | E361: =SUMIFS(Player_Season!$E$2:$E$1869,Player_Season!$B$2:$B$1869,A361) -> 5 | F361: =SUMIFS(Player_Season!$F$2:$F$1869,Player_Season!$B$2:$B$1869,A361) -> 4 | G361: =IF(E361>0,F361/E361,"") -> 0.8 | H361: M
A362: Jake Naso | B362: 1 | C362: 2025 | D362: 2025 | E362: =SUMIFS(Player_Season!$E$2:$E$1869,Player_Season!$B$2:$B$1869,A362) -> 4 | F362: =SUMIFS(Player_Season!$F$2:$F$1869,Player_Season!$B$2:$B$1869,A362) -> 4 | G362: =IF(E362>0,F362/E362,"") -> 1 | H362: FO
A363: Cullen Brown | B363: 1 | C363: 2026 | D363: 2026 | E363: =SUMIFS(Player_Season!$E$2:$E$1869,Player_Season!$B$2:$B$1869,A363) -> 10 | F363: =SUMIFS(Player_Season!$F$2:$F$1869,Player_Season!$B$2:$B$1869,A363) -> 4 | G363: =IF(E363>0,F363/E363,"") -> 0.4 | H363: D
A364: Hunter Drouin | B364: 1 | C364: 2026 | D364: 2026 | E364: =SUMIFS(Player_Season!$E$2:$E$1869,Player_Season!$B$2:$B$1869,A364) -> 2 | F364: =SUMIFS(Player_Season!$F$2:$F$1869,Player_Season!$B$2:$B$1869,A364) -> 4 | G364: =IF(E364>0,F364/E364,"") -> 2 | H364: A
A365: James Pannell | B365: 3 | C365: 2019 | D365: 2021 | E365: =SUMIFS(Player_Season!$E$2:$E$1869,Player_Season!$B$2:$B$1869,A365) -> 2 | F365: =SUMIFS(Player_Season!$F$2:$F$1869,Player_Season!$B$2:$B$1869,A365) -> 4 | G365: =IF(E365>0,F365/E365,"") -> 2 | H365: A
A366: Max Merklinger | B366: 1 | C366: 2025 | D366: 2025 | E366: =SUMIFS(Player_Season!$E$2:$E$1869,Player_Season!$B$2:$B$1869,A366) -> 2 | F366: =SUMIFS(Player_Season!$F$2:$F$1869,Player_Season!$B$2:$B$1869,A366) -> 4 | G366: =IF(E366>0,F366/E366,"") -> 2 | H366: A
A367: Billy Dwan | B367: 1 | C367: 2026 | D367: 2026 | E367: =SUMIFS(Player_Season!$E$2:$E$1869,Player_Season!$B$2:$B$1869,A367) -> 8 | F367: =SUMIFS(Player_Season!$F$2:$F$1869,Player_Season!$B$2:$B$1869,A367) -> 4 | G367: =IF(E367>0,F367/E367,"") -> 0.5 | H367: D
A368: Michael Lampert | B368: 2 | C368: 2025 | D368: 2026 | E368: =SUMIFS(Player_Season!$E$2:$E$1869,Player_Season!$B$2:$B$1869,A368) -> 4 | F368: =SUMIFS(Player_Season!$F$2:$F$1869,Player_Season!$B$2:$B$1869,A368) -> 4 | G368: =IF(E368>0,F368/E368,"") -> 1 | H368: A
A369: Andrew Newbold | B369: 2 | C369: 2021 | D369: 2022 | E369: =SUMIFS(Player_Season!$E$2:$E$1869,Player_Season!$B$2:$B$1869,A369) -> 8 | F369: =SUMIFS(Player_Season!$F$2:$F$1869,Player_Season!$B$2:$B$1869,A369) -> 4 | G369: =IF(E369>0,F369/E369,"") -> 0.5 | H369: D
... A405: Austin Kaut | B405: 6 | C405: 2021 | D405: 2026 | E405: =SUMIFS(Player_Season!$E$2:$E$1869,Player_Season!$B$2:$B$1869,A405) -> 22 | F405: =SUMIFS(Player_Season!$F$2:$F$1869,Player_Season!$B$2:$B$1869,A405) -> 2 | G405: =IF(E405>0,F405/E405,"") -> 0.090909091 | H405: G
A406: Alec Tulett | B406: 1 | C406: 2019 | D406: 2019 | E406: =SUMIFS(Player_Season!$E$2:$E$1869,Player_Season!$B$2:$B$1869,A406) -> 10 | F406: =SUMIFS(Player_Season!$F$2:$F$1869,Player_Season!$B$2:$B$1869,A406) -> 2 | G406: =IF(E406>0,F406/E406,"") -> 0.2
A407: Austin Pifani | B407: 5 | C407: 2019 | D407: 2023 | E407: =SUMIFS(Player_Season!$E$2:$E$1869,Player_Season!$B$2:$B$1869,A407) -> 15 | F407: =SUMIFS(Player_Season!$F$2:$F$1869,Player_Season!$B$2:$B$1869,A407) -> 2 | G407: =IF(E407>0,F407/E407,"") -> 0.13333333 | H407: D
A408: Gavin Adler | B408: 4 | C408: 2023 | D408: 2026 | E408: =SUMIFS(Player_Season!$E$2:$E$1869,Player_Season!$B$2:$B$1869,A408) -> 38 | F408: =SUMIFS(Player_Season!$F$2:$F$1869,Player_Season!$B$2:$B$1869,A408) -> 2 | G408: =IF(E408>0,F408/E408,"") -> 0.052631579 | H408: D
A409: Marcus Hudgins | B409: 3 | C409: 2024 | D409: 2026 | E409: =SUMIFS(Player_Season!$E$2:$E$1869,Player_Season!$B$2:$B$1869,A409) -> 26 | F409: =SUMIFS(Player_Season!$F$2:$F$1869,Player_Season!$B$2:$B$1869,A409) -> 2 | G409: =IF(E409>0,F409/E409,"") -> 0.076923077 | H409: D
A410: Jack Posey | B410: 3 | C410: 2024 | D410: 2026 | E410: =SUMIFS(Player_Season!$E$2:$E$1869,Player_Season!$B$2:$B$1869,A410) -> 15 | F410: =SUMIFS(Player_Season!$F$2:$F$1869,Player_Season!$B$2:$B$1869,A410) -> 2 | G410: =IF(E410>0,F410/E410,"") -> 0.13333333 | H410: D
A411: JD Colarusso | B411: 2 | C411: 2021 | D411: 2022 | E411: =SUMIFS(Player_Season!$E$2:$E$1869,Player_Season!$B$2:$B$1869,A411) -> 11 | F411: =SUMIFS(Player_Season!$F$2:$F$1869,Player_Season!$B$2:$B$1869,A411) -> 2 | G411: =IF(E411>0,F411/E411,"") -> 0.18181818 | H411: G
A412: Brendan Lavelle | B412: 2 | C412: 2025 | D412: 2026 | E412: =SUMIFS(Player_Season!$E$2:$E$1869,Player_Season!$B$2:$B$1869,A412) -> 22 | F412: =SUMIFS(Player_Season!$F$2:$F$1869,Player_Season!$B$2:$B$1869,A412) -> 2 | G412: =IF(E412>0,F412/E412,"") -> 0.090909091 | H412: D
A413: BJ Farrare | B413: 3 | C413: 2024 | D413: 2026 | E413: =SUMIFS(Player_Season!$E$2:$E$1869,Player_Season!$B$2:$B$1869,A413) -> 23 | F413: =SUMIFS(Player_Season!$F$2:$F$1869,Player_Season!$B$2:$B$1869,A413) -> 2 | G413: =IF(E413>0,F413/E413,"") -> 0.086956522 | H413: LSM
A414: Drew Adams | B414: 4 | C414: 2019 | D414: 2022 | E414: =SUMIFS(Player_Season!$E$2:$E$1869,Player_Season!$B$2:$B$1869,A414) -> 21 | F414: =SUMIFS(Player_Season!$F$2:$F$1869,Player_Season!$B$2:$B$1869,A414) -> 2 | G414: =IF(E414>0,F414/E414,"") -> 0.095238095 | H414: G
A415: Matt Rahill | B415: 2 | C415: 2022 | D415: 2023 | E415: =SUMIFS(Player_Season!$E$2:$E$1869,Player_Season!$B$2:$B$1869,A415) -> 12 | F415: =SUMIFS(Player_Season!$F$2:$F$1869,Player_Season!$B$2:$B$1869,A415) -> 2 | G415: =IF(E415>0,F415/E415,"") -> 0.16666667 | H415: D
A416: James Barclay | B416: 6 | C416: 2019 | D416: 2024 | E416: =SUMIFS(Player_Season!$E$2:$E$1869,Player_Season!$B$2:$B$1869,A416) -> 19 | F416: =SUMIFS(Player_Season!$F$2:$F$1869,Player_Season!$B$2:$B$1869,A416) -> 2 | G416: =IF(E416>0,F416/E416,"") -> 0.10526316 | H416: D
A417: Eric Kolar | B417: 1 | C417: 2026 | D417: 2026 | E417: =SUMIFS(Player_Season!$E$2:$E$1869,Player_Season!$B$2:$B$1869,A417) -> 7 | F417: =SUMIFS(Player_Season!$F$2:$F$1869,Player_Season!$B$2:$B$1869,A417) -> 2 | G417: =IF(E417>0,F417/E417,"") -> 0.28571429 | H417: SSDM
...

Sheet Literature
A1: Study | B1: Population | C1: Measure | D1: Value | E1: SD | F1: Unit | G1: Note
A2: Vincent et al. 2015 (DOI 10.1080/14763141.2015.1084034) | B2: Professional players (n=6 of 39) | C2: Ball speed | D2: 138 | E2: 7 | F2: km/h | G2: Lab overhead shot; not PLL-specific
A3: Vincent et al. 2015 | B3: High-school players | C3: Ball speed | D3: 112 | E3: 15 | F3: km/h | G3: Comparison group
A4: Vincent et al. 2015 | B4: Professional vs HS/collegiate | C4: Crosse angular velocity | D4: 21 | F4: % faster | G4: Published comparison
